Workbook
Name Slicer_City_tier: #N/A
Name Slicer_City_tier1: #N/A
Name Slicer_Diabetes_Status: #N/A
Name Slicer_Hospital_tier: #N/A
Name Slicer_Weight_Status: #N/A

Sheet Customer Name
A1: Customer ID | B1: name | C1: Title | D1: First name | E1: Last name
A2: Id1 | B2: Hawks, Ms. Kelly | C2: Ms. | D2: Kelly | E2: Hawks
A3: Id2 | B3: Lehner, Mr. Matthew D | C3: Mr. | D3: Matthew D | E3: Lehner
A4: Id3 | B4: Lu, Mr. Phil | C4: Mr. | D4: Phil | E4: Lu
A5: Id4 | B5: Osborne, Ms. Kelsey | C5: Ms. | D5: Kelsey | E5: Osborne
A6: Id5 | B6: Kadala, Ms. Kristyn | C6: Ms. | D6: Kristyn | E6: Kadala
A7: Id6 | B7: Baker, Mr. Russell B. | C7: Mr. | D7: Russell B. | E7: Baker
A8: Id7 | B8: Macpherson, Mr. Scott | C8: Mr. | D8: Scott | E8: Macpherson
A9: Id8 | B9: Hallman, Mr. Stephen | C9: Mr. | D9: Stephen | E9: Hallman
A10: Id9 | B10: Moran, Mr. Patrick R. | C10: Mr. | D10: Patrick R. | E10: Moran
A11: Id10 | B11: Benner, Ms. Brooke N. | C11: Ms. | D11: Brooke N. | E11: Benner
A12: Id11 | B12: Fierro Vargas, Ms. Paola Andrea | C12: Ms. | D12: Paola Andrea | E12: Fierro Vargas
... A2336: Id2335 | B2336: German, Mr. Aaron K | C2336: Mr. | D2336: Aaron K | E2336: German

Sheet Medical Examination
A1: Customer ID | B1: BMI | C1: HBA1C | D1: Heart Issues | E1: Any Transplants | F1: Cancer history | G1: NumberOfMajorSurgeries | H1: smoker | J1: Smoker Imputed | K1: NumberOfMajorSurgeries | L1: Weight Status | M1: Diabetes Status | O1: Most Value repeated in smoker
A2: Id1 | B2: 47.41 | C2: 7.47 | D2: No | E2: No | F2: No | G2: No major surgery | H2: yes | J2: =IF(Table7[[#This Row],[smoker]]="?","No",Table7[[#This Row],[smoker]]) -> yes | K2: =IFERROR(VALUE(Table7[[#This Row],[NumberOfMajorSurgeries]]),0) -> 0 | L2: =IF(B2 < 18.5, "Underweight", IF(B2 < 25, "Normal Weight", IF(B2 < 30, "Overweight", "Obesity"))) -> Obesity | M2: =IF(C2<5.7,"Normal", IF(C2<6.5,"Prediabetes", IF(C2<7,"Diabetes", "Diabetes"))) -> Diabetes | O2: =COUNTIF(Table7[smoker],"Yes") -> 488 | P2: Yes
A3: Id2 | B3: 30.36 | C3: 5.77 | D3: No | E3: No | F3: No | G3: No major surgery | H3: yes | J3: =IF(Table7[[#This Row],[smoker]]="?","No",Table7[[#This Row],[smoker]]) -> yes | K3: =IFERROR(VALUE(Table7[[#This Row],[NumberOfMajorSurgeries]]),0) -> 0 | L3: =IF(B3 < 18.5, "Underweight", IF(B3 < 25, "Normal Weight", IF(B3 < 30, "Overweight", "Obesity"))) -> Obesity | M3: =IF(C3<5.7,"Normal", IF(C3<6.5,"Prediabetes", IF(C3<7,"Diabetes", "Diabetes"))) -> Prediabetes | O3: =COUNTIF(Table7[smoker],"No") -> 1845 | P3: NO
A4: Id3 | B4: 34.485 | C4: 11.87 | D4: yes | E4: No | F4: No | G4: 2 | H4: yes | J4: =IF(Table7[[#This Row],[smoker]]="?","No",Table7[[#This Row],[smoker]]) -> yes | K4: =IFERROR(VALUE(Table7[[#This Row],[NumberOfMajorSurgeries]]),0) -> 2 | L4: =IF(B4 < 18.5, "Underweight", IF(B4 < 25, "Normal Weight", IF(B4 < 30, "Overweight", "Obesity"))) -> Obesity | M4: =IF(C4<5.7,"Normal", IF(C4<6.5,"Prediabetes", IF(C4<7,"Diabetes", "Diabetes"))) -> Diabetes
A5: Id4 | B5: 38.095 | C5: 6.05 | D5: No | E5: No | F5: No | G5: No major surgery | H5: yes | J5: =IF(Table7[[#This Row],[smoker]]="?","No",Table7[[#This Row],[smoker]]) -> yes | K5: =IFERROR(VALUE(Table7[[#This Row],[NumberOfMajorSurgeries]]),0) -> 0 | L5: =IF(B5 < 18.5, "Underweight", IF(B5 < 25, "Normal Weight", IF(B5 < 30, "Overweight", "Obesity"))) -> Obesity | M5: =IF(C5<5.7,"Normal", IF(C5<6.5,"Prediabetes", IF(C5<7,"Diabetes", "Diabetes"))) -> Prediabetes
A6: Id5 | B6: 35.53 | C6: 5.45 | D6: No | E6: No | F6: No | G6: No major surgery | H6: yes | J6: =IF(Table7[[#This Row],[smoker]]="?","No",Table7[[#This Row],[smoker]]) -> yes | K6: =IFERROR(VALUE(Table7[[#This Row],[NumberOfMajorSurgeries]]),0) -> 0 | L6: =IF(B6 < 18.5, "Underweight", IF(B6 < 25, "Normal Weight", IF(B6 < 30, "Overweight", "Obesity"))) -> Obesity | M6: =IF(C6<5.7,"Normal", IF(C6<6.5,"Prediabetes", IF(C6<7,"Diabetes", "Diabetes"))) -> Normal
A7: Id6 | B7: 32.8 | C7: 6.59 | D7: No | E7: No | F7: No | G7: No major surgery | H7: yes | J7: =IF(Table7[[#This Row],[smoker]]="?","No",Table7[[#This Row],[smoker]]) -> yes | K7: =IFERROR(VALUE(Table7[[#This Row],[NumberOfMajorSurgeries]]),0) -> 0 | L7: =IF(B7 < 18.5, "Underweight", IF(B7 < 25, "Normal Weight", IF(B7 < 30, "Overweight", "Obesity"))) -> Obesity | M7: =IF(C7<5.7,"Normal", IF(C7<6.5,"Prediabetes", IF(C7<7,"Diabetes", "Diabetes"))) -> Diabetes
A8: Id7 | B8: 36.4 | C8: 6.07 | D8: No | E8: No | F8: No | G8: No major surgery | H8: yes | J8: =IF(Table7[[#This Row],[smoker]]="?","No",Table7[[#This Row],[smoker]]) -> yes | K8: =IFERROR(VALUE(Table7[[#This Row],[NumberOfMajorSurgeries]]),0) -> 0 | L8: =IF(B8 < 18.5, "Underweight", IF(B8 < 25, "Normal Weight", IF(B8 < 30, "Overweight", "Obesity"))) -> Obesity | M8: =IF(C8<5.7,"Normal", IF(C8<6.5,"Prediabetes", IF(C8<7,"Diabetes", "Diabetes"))) -> Prediabetes
A9: Id8 | B9: 36.96 | C9: 7.93 | D9: No | E9: No | F9: No | G9: 3 | H9: yes | J9: =IF(Table7[[#This Row],[smoker]]="?","No",Table7[[#This Row],[smoker]]) -> yes | K9: =IFERROR(VALUE(Table7[[#This Row],[NumberOfMajorSurgeries]]),0) -> 3 | L9: =IF(B9 < 18.5, "Underweight", IF(B9 < 25, "Normal Weight", IF(B9 < 30, "Overweight", "Obesity"))) -> Obesity | M9: =IF(C9<5.7,"Normal", IF(C9<6.5,"Prediabetes", IF(C9<7,"Diabetes", "Diabetes"))) -> Diabetes
A10: Id9 | B10: 41.14 | C10: 9.58 | D10: yes | E10: No | F10: Yes | G10: 1 | H10: yes | J10: =IF(Table7[[#This Row],[smoker]]="?","No",Table7[[#This Row],[smoker]]) -> yes | K10: =IFERROR(VALUE(Table7[[#This Row],[NumberOfMajorSurgeries]]),0) -> 1 | L10: =IF(B10 < 18.5, "Underweight", IF(B10 < 25, "Normal Weight", IF(B10 < 30, "Overweight", "Obesity"))) -> Obesity | M10: =IF(C10<5.7,"Normal", IF(C10<6.5,"Prediabetes", IF(C10<7,"Diabetes", "Diabetes"))) -> Diabetes
A11: Id10 | B11: 38.06 | C11: 10.79 | D11: No | E11: No | F11: No | G11: No major surgery | H11: yes | J11: =IF(Table7[[#This Row],[smoker]]="?","No",Table7[[#This Row],[smoker]]) -> yes | K11: =IFERROR(VALUE(Table7[[#This Row],[NumberOfMajorSurgeries]]),0) -> 0 | L11: =IF(B11 < 18.5, "Underweight", IF(B11 < 25, "Normal Weight", IF(B11 < 30, "Overweight", "Obesity"))) -> Obesity | M11: =IF(C11<5.7,"Normal", IF(C11<6.5,"Prediabetes", IF(C11<7,"Diabetes", "Diabetes"))) -> Diabetes
A12: Id11 | B12: 37.7 | C12: 5.96 | D12: yes | E12: No | F12: No | G12: 2 | H12: yes | J12: =IF(Table7[[#This Row],[smoker]]="?","No",Table7[[#This Row],[smoker]]) -> yes | K12: =IFERROR(VALUE(Table7[[#This Row],[NumberOfMajorSurgeries]]),0) -> 2 | L12: =IF(B12 < 18.5, "Underweight", IF(B12 < 25, "Normal Weight", IF(B12 < 30, "Overweight", "Obesity"))) -> Obesity | M12: =IF(C12<5.7,"Normal", IF(C12<6.5,"Prediabetes", IF(C12<7,"Diabetes", "Diabetes"))) -> Prediabetes
A13: Id12 | B13: 42.13 | C13: 11.9 | D13: No | E13: No | F13: No | G13: No major surgery | H13: yes | J13: =IF(Table7[[#This Row],[smoker]]="?","No",Table7[[#This Row],[smoker]]) -> yes | K13: =IFERROR(VALUE(Table7[[#This Row],[NumberOfMajorSurgeries]]),0) -> 0 | L13: =IF(B13 < 18.5, "Underweight", IF(B13 < 25, "Normal Weight", IF(B13 < 30, "Overweight", "Obesity"))) -> Obesity | M13: =IF(C13<5.7,"Normal", IF(C13<6.5,"Prediabetes", IF(C13<7,"Diabetes", "Diabetes"))) -> Diabetes
A14: Id13 | B14: 40.92 | C14: 8.41 | D14: No | E14: No | F14: No | G14: No major surgery | H14: yes | J14: =IF(Table7[[#This Row],[smoker]]="?","No",Table7[[#This Row],[smoker]]) -> yes | K14: =IFERROR(VALUE(Table7[[#This Row],[NumberOfMajorSurgeries]]),0) -> 0 | L14: =IF(B14 < 18.5, "Underweight", IF(B14 < 25, "Normal Weight", IF(B14 < 30, "Overweight", "Obesity"))) -> Obesity | M14: =IF(C14<5.7,"Normal", IF(C14<6.5,"Prediabetes", IF(C14<7,"Diabetes", "Diabetes"))) -> Diabetes
A15: Id14 | B15: 40.565 | C15: 7.02 | D15: No | E15: No | F15: No | G15: No major surgery | H15: yes | J15: =IF(Table7[[#This Row],[smoker]]="?","No",Table7[[#This Row],[smoker]]) -> yes | K15: =IFERROR(VALUE(Table7[[#This Row],[NumberOfMajorSurgeries]]),0) -> 0 | L15: =IF(B15 < 18.5, "Underweight", IF(B15 < 25, "Normal Weight", IF(B15 < 30, "Overweight", "Obesity"))) -> Obesity | M15: =IF(C15<5.7,"Normal", IF(C15<6.5,"Prediabetes", IF(C15<7,"Diabetes", "Diabetes"))) -> Diabetes
A16: Id15 | B16: 36.385 | C16: 7.59 | D16: yes | E16: No | F16: No | G16: 2 | H16: yes | J16: =IF(Table7[[#This Row],[smoker]]="?","No",Table7[[#This Row],[smoker]]) -> yes | K16: =IFERROR(VALUE(Table7[[#This Row],[NumberOfMajorSurgeries]]),0) -> 2 | L16: =IF(B16 < 18.5, "Underweight", IF(B16 < 25, "Normal Weight", IF(B16 < 30, "Overweight", "Obesity"))) -> Obesity | M16: =IF(C16<5.7,"Normal", IF(C16<6.5,"Prediabetes", IF(C16<7,"Diabetes", "Diabetes"))) -> Diabetes
A17: Id16 | B17: 39.9 | C17: 11.32 | D17: No | E17: No | F17: No | G17: No major surgery | H17: yes | J17: =IF(Table7[[#This Row],[smoker]]="?","No",Table7[[#This Row],[smoker]]) -> yes | K17: =IFERROR(VALUE(Table7[[#This Row],[NumberOfMajorSurgeries]]),0) -> 0 | L17: =IF(B17 < 18.5, "Underweight", IF(B17 < 25, "Normal Weight", IF(B17 < 30, "Overweight", "Obesity"))) -> Obesity | M17: =IF(C17<5.7,"Normal", IF(C17<6.5,"Prediabetes", IF(C17<7,"Diabetes", "Diabetes"))) -> Diabetes
A18: Id17 | B18: 33.8 | C18: 7.67 | D18: No | E18: No | F18: No | G18: 3 | H18: yes | J18: =IF(Table7[[#This Row],[smoker]]="?","No",Table7[[#This Row],[smoker]]) -> yes | K18: =IFERROR(VALUE(Table7[[#This Row],[NumberOfMajorSurgeries]]),0) -> 3 | L18: =IF(B18 < 18.5, "Underweight", IF(B18 < 25, "Normal Weight", IF(B18 < 30, "Overweight", "Obesity"))) -> Obesity | M18: =IF(C18<5.7,"Normal", IF(C18<6.5,"Prediabetes", IF(C18<7,"Diabetes", "Diabetes"))) -> Diabetes
A19: Id18 | B19: 36.765 | C19: 7.29 | D19: yes | E19: No | F19: Yes | G19: 1 | H19: yes | J19: =IF(Table7[[#This Row],[smoker]]="?","No",Table7[[#This Row],[smoker]]) -> yes | K19: =IFERROR(VALUE(Table7[[#This Row],[NumberOfMajorSurgeries]]),0) -> 1 | L19: =IF(B19 < 18.5, "Underweight", IF(B19 < 25, "Normal Weight", IF(B19 < 30, "Overweight", "Obesity"))) -> Obesity | M19: =IF(C19<5.7,"Normal", IF(C19<6.5,"Prediabetes", IF(C19<7,"Diabetes", "Diabetes"))) -> Diabetes
A20: Id19 | B20: 36.955 | C20: 4.72 | D20: yes | E20: No | F20: No | G20: 1 | H20: yes | J20: =IF(Table7[[#This Row],[smoker]]="?","No",Table7[[#This Row],[smoker]]) -> yes | K20: =IFERROR(VALUE(Table7[[#This Row],[NumberOfMajorSurgeries]]),0) -> 1 | L20: =IF(B20 < 18.5, "Underweight", IF(B20 < 25, "Normal Weight", IF(B20 < 30, "Overweight", "Obesity"))) -> Obesity | M20: =IF(C20<5.7,"Normal", IF(C20<6.5,"Prediabetes", IF(C20<7,"Diabetes", "Diabetes"))) -> Normal
A21: Id20 | B21: 42.9 | C21: 11.41 | D21: No | E21: No | F21: No | G21: No major surgery | H21: yes | J21: =IF(Table7[[#This Row],[smoker]]="?","No",Table7[[#This Row],[smoker]]) -> yes | K21: =IFERROR(VALUE(Table7[[#This Row],[NumberOfMajorSurgeries]]),0) -> 0 | L21: =IF(B21 < 18.5, "Underweight", IF(B21 < 25, "Normal Weight", IF(B21 < 30, "Overweight", "Obesity"))) -> Obesity | M21: =IF(C21<5.7,"Normal", IF(C21<6.5,"Prediabetes", IF(C21<7,"Diabetes", "Diabetes"))) -> Diabetes
A22: Id21 | B22: 36.3 | C22: 11.5 | D22: yes | E22: No | F22: No | G22: 2 | H22: yes | J22: =IF(Table7[[#This Row],[smoker]]="?","No",Table7[[#This Row],[smoker]]) -> yes | K22: =IFERROR(VALUE(Table7[[#This Row],[NumberOfMajorSurgeries]]),0) -> 2 | L22: =IF(B22 < 18.5, "Underweight", IF(B22 < 25, "Normal Weight", IF(B22 < 30, "Overweight", "Obesity"))) -> Obesity | M22: =IF(C22<5.7,"Normal", IF(C22<6.5,"Prediabetes", IF(C22<7,"Diabetes", "Diabetes"))) -> Diabetes
A23: Id22 | B23: 32.2 | C23: 6.22 | D23: yes | E23: No | F23: No | G23: 2 | H23: yes | J23: =IF(Table7[[#This Row],[smoker]]="?","No",Table7[[#This Row],[smoker]]) -> yes | K23: =IFERROR(VALUE(Table7[[#This Row],[NumberOfMajorSurgeries]]),0) -> 2 | L23: =IF(B23 < 18.5, "Underweight", IF(B23 < 25, "Normal Weight", IF(B23 < 30, "Overweight", "Obesity"))) -> Obesity | M23: =IF(C23<5.7,"Normal", IF(C23<6.5,"Prediabetes", IF(C23<7,"Diabetes", "Diabetes"))) -> Prediabetes
A24: Id23 | B24: 31.3 | C24: 11.38 | D24: No | E24: No | F24: No | G24: 3 | H24: yes | J24: =IF(Table7[[#This Row],[smoker]]="?","No",Table7[[#This Row],[smoker]]) -> yes | K24: =IFERROR(VALUE(Table7[[#This Row],[NumberOfMajorSurgeries]]),0) -> 3 | L24: =IF(B24 < 18.5, "Underweight", IF(B24 < 25, "Normal Weight", IF(B24 < 30, "Overweight", "Obesity"))) -> Obesity | M24: =IF(C24<5.7,"Normal", IF(C24<6.5,"Prediabetes", IF(C24<7,"Diabetes", "Diabetes"))) -> Diabetes
A25: Id24 | B25: 41.8 | C25: 7.89 | D25: yes | E25: No | F25: No | G25: 2 | H25: yes | J25: =IF(Table7[[#This Row],[smoker]]="?","No",Table7[[#This Row],[smoker]]) -> yes | K25: =IFERROR(VALUE(Table7[[#This Row],[NumberOfMajorSurgeries]]),0) -> 2 | L25: =IF(B25 < 18.5, "Underweight", IF(B25 < 25, "Normal Weight", IF(B25 < 30, "Overweight", "Obesity"))) -> Obesity | M25: =IF(C25<5.7,"Normal", IF(C25<6.5,"Prediabetes", IF(C25<7,"Diabetes", "Diabetes"))) -> Diabetes
A26: Id25 | B26: 35.09 | C26: 4.38 | D26: yes | E26: No | F26: No | G26: 2 | H26: yes | J26: =IF(Table7[[#This Row],[smoker]]="?","No",Table7[[#This Row],[smoker]]) -> yes | K26: =IFERROR(VALUE(Table7[[#This Row],[NumberOfMajorSurgeries]]),0) -> 2 | L26: =IF(B26 < 18.5, "Underweight", IF(B26 < 25, "Normal Weight", IF(B26 < 30, "Overweight", "Obesity"))) -> Obesity | M26: =IF(C26<5.7,"Normal", IF(C26<6.5,"Prediabetes", IF(C26<7,"Diabetes", "Diabetes"))) -> Normal
A27: Id26 | B27: 33.88 | C27: 7.01 | D27: No | E27: No | F27: No | G27: 3 | H27: yes | J27: =IF(Table7[[#This Row],[smoker]]="?","No",Table7[[#This Row],[smoker]]) -> yes | K27: =IFERROR(VALUE(Table7[[#This Row],[NumberOfMajorSurgeries]]),0) -> 3 | L27: =IF(B27 < 18.5, "Underweight", IF(B27 < 25, "Normal Weight", IF(B27 < 30, "Overweight", "Obesity"))) -> Obesity | M27: =IF(C27<5.7,"Normal", IF(C27<6.5,"Prediabetes", IF(C27<7,"Diabetes", "Diabetes"))) -> Diabetes
A28: Id27 | B28: 30.875 | C28: 11.88 | D28: No | E28: No | F28: No | G28: No major surgery | H28: yes | J28: =IF(Table7[[#This Row],[smoker]]="?","No",Table7[[#This Row],[smoker]]) -> yes | K28: =IFERROR(VALUE(Table7[[#This Row],[NumberOfMajorSurgeries]]),0) -> 0 | L28: =IF(B28 < 18.5, "Underweight", IF(B28 < 25, "Normal Weight", IF(B28 < 30, "Overweight", "Obesity"))) -> Obesity | M28: =IF(C28<5.7,"Normal", IF(C28<6.5,"Prediabetes", IF(C28<7,"Diabetes", "Diabetes"))) -> Diabetes
A29: Id28 | B29: 36.86 | C29: 5.19 | D29: yes | E29: No | F29: Yes | G29: 1 | H29: yes | J29: =IF(Table7[[#This Row],[smoker]]="?","No",Table7[[#This Row],[smoker]]) -> yes | K29: =IFERROR(VALUE(Table7[[#This Row],[NumberOfMajorSurgeries]]),0) -> 1 | L29: =IF(B29 < 18.5, "Underweight", IF(B29 < 25, "Normal Weight", IF(B29 < 30, "Overweight", "Obesity"))) -> Obesity | M29: =IF(C29<5.7,"Normal", IF(C29<6.5,"Prediabetes", IF(C29<7,"Diabetes", "Diabetes"))) -> Normal
A30: Id29 | B30: 35.86 | C30: 6.74 | D30: yes | E30: No | F30: No | G30: 2 | H30: yes | J30: =IF(Table7[[#This Row],[smoker]]="?","No",Table7[[#This Row],[smoker]]) -> yes | K30: =IFERROR(VALUE(Table7[[#This Row],[NumberOfMajorSurgeries]]),0) -> 2 | L30: =IF(B30 < 18.5, "Underweight", IF(B30 < 25, "Normal Weight", IF(B30 < 30, "Overweight", "Obesity"))) -> Obesity | M30: =IF(C30<5.7,"Normal", IF(C30<6.5,"Prediabetes", IF(C30<7,"Diabetes", "Diabetes"))) -> Diabetes
A31: Id30 | B31: 37.05 | C31: 8.44 | D31: No | E31: No | F31: No | G31: No major surgery | H31: yes | J31: =IF(Table7[[#This Row],[smoker]]="?","No",Table7[[#This Row],[smoker]]) -> yes | K31: =IFERROR(VALUE(Table7[[#This Row],[NumberOfMajorSurgeries]]),0) -> 0 | L31: =IF(B31 < 18.5, "Underweight", IF(B31 < 25, "Normal Weight", IF(B31 < 30, "Overweight", "Obesity"))) -> Obesity | M31: =IF(C31<5.7,"Normal", IF(C31<6.5,"Prediabetes", IF(C31<7,"Diabetes", "Diabetes"))) -> Diabetes
A32: Id31 | B32: 43.89 | C32: 8.71 | D32: No | E32: No | F32: No | G32: No major surgery | H32: yes | J32: =IF(Table7[[#This Row],[smoker]]="?","No",Table7[[#This Row],[smoker]]) -> yes | K32: =IFERROR(VALUE(Table7[[#This Row],[NumberOfMajorSurgeries]]),0) -> 0 | L32: =IF(B32 < 18.5, "Underweight", IF(B32 < 25, "Normal Weight", IF(B32 < 30, "Overweight", "Obesity"))) -> Obesity | M32: =IF(C32<5.7,"Normal", IF(C32<6.5,"Prediabetes", IF(C32<7,"Diabetes", "Diabetes"))) -> Diabetes
A33: Id32 | B33: 42.35 | C33: 5.08 | D33: yes | E33: No | F33: No | G33: No major surgery | H33: yes | J33: =IF(Table7[[#This Row],[smoker]]="?","No",Table7[[#This Row],[smoker]]) -> yes | K33: =IFERROR(VALUE(Table7[[#This Row],[NumberOfMajorSurgeries]]),0) -> 0 | L33: =IF(B33 < 18.5, "Underweight", IF(B33 < 25, "Normal Weight", IF(B33 < 30, "Overweight", "Obesity"))) -> Obesity | M33: =IF(C33<5.7,"Normal", IF(C33<6.5,"Prediabetes", IF(C33<7,"Diabetes", "Diabetes"))) -> Normal
A34: Id33 | B34: 31.35 | C34: 6.86 | D34: No | E34: No | F34: No | G34: No major surgery | H34: yes | J34: =IF(Table7[[#This Row],[smoker]]="?","No",Table7[[#This Row],[smoker]]) -> yes | K34: =IFERROR(VALUE(Table7[[#This Row],[NumberOfMajorSurgeries]]),0) -> 0 | L34: =IF(B34 < 18.5, "Underweight", IF(B34 < 25, "Normal Weight", IF(B34 < 30, "Overweight", "Obesity"))) -> Obesity | M34: =IF(C34<5.7,"Normal", IF(C34<6.5,"Prediabetes", IF(C34<7,"Diabetes", "Diabetes"))) -> Diabetes
A35: Id34 | B35: 47.6 | C35: 5.95 | D35: yes | E35: No | F35: No | G35: No major surgery | H35: yes | J35: =IF(Table7[[#This Row],[smoker]]="?","No",Table7[[#This Row],[smoker]]) -> yes | K35: =IFERROR(VALUE(Table7[[#This Row],[NumberOfMajorSurgeries]]),0) -> 0 | L35: =IF(B35 < 18.5, "Underweight", IF(B35 < 25, "Normal Weight", IF(B35 < 30, "Overweight", "Obesity"))) -> Obesity | M35: =IF(C35<5.7,"Normal", IF(C35<6.5,"Prediabetes", IF(C35<7,"Diabetes", "Diabetes"))) -> Prediabetes
A36: Id35 | B36: 46.2 | C36: 6.09 | D36: No | E36: No | F36: Yes | G36: 1 | H36: yes | J36: =IF(Table7[[#This Row],[smoker]]="?","No",Table7[[#This Row],[smoker]]) -> yes | K36: =IFERROR(VALUE(Table7[[#This Row],[NumberOfMajorSurgeries]]),0) -> 1 | L36: =IF(B36 < 18.5, "Underweight", IF(B36 < 25, "Normal Weight", IF(B36 < 30, "Overweight", "Obesity"))) -> Obesity | M36: =IF(C36<5.7,"Normal", IF(C36<6.5,"Prediabetes", IF(C36<7,"Diabetes", "Diabetes"))) -> Prediabetes
A37: Id36 | B37: 32.015 | C37: 11.75 | D37: No | E37: No | F37: No | G37: No major surgery | H37: yes | J37: =IF(Table7[[#This Row],[smoker]]="?","No",Table7[[#This Row],[smoker]]) -> yes | K37: =IFERROR(VALUE(Table7[[#This Row],[NumberOfMajorSurgeries]]),0) -> 0 | L37: =IF(B37 < 18.5, "Underweight", IF(B37 < 25, "Normal Weight", IF(B37 < 30, "Overweight", "Obesity"))) -> Obesity | M37: =IF(C37<5.7,"Normal", IF(C37<6.5,"Prediabetes", IF(C37<7,"Diabetes", "Diabetes"))) -> Diabetes
A38: Id37 | B38: 40.565 | C38: 7.37 | D38: No | E38: No | F38: No | G38: No major surgery | H38: yes | J38: =IF(Table7[[#This Row],[smoker]]="?","No",Table7[[#This Row],[smoker]]) -> yes | K38: =IFERROR(VALUE(Table7[[#This Row],[NumberOfMajorSurgeries]]),0) -> 0 | L38: =IF(B38 < 18.5, "Underweight", IF(B38 < 25, "Normal Weight", IF(B38 < 30, "Overweight", "Obesity"))) -> Obesity | M38: =IF(C38<5.7,"Normal", IF(C38<6.5,"Prediabetes", IF(C38<7,"Diabetes", "Diabetes"))) -> Diabetes
A39: Id38 | B39: 32.45 | C39: 11.91 | D39: No | E39: No | F39: No | G39: No major surgery | H39: yes | J39: =IF(Table7[[#This Row],[smoker]]="?","No",Table7[[#This Row],[smoker]]) -> yes | K39: =IFERROR(VALUE(Table7[[#This Row],[NumberOfMajorSurgeries]]),0) -> 0 | L39: =IF(B39 < 18.5, "Underweight", IF(B39 < 25, "Normal Weight", IF(B39 < 30, "Overweight", "Obesity"))) -> Obesity | M39: =IF(C39<5.7,"Normal", IF(C39<6.5,"Prediabetes", IF(C39<7,"Diabetes", "Diabetes"))) -> Diabetes
A40: Id39 | B40: 34.96 | C40: 6.52 | D40: No | E40: No | F40: No | G40: No major surgery | H40: yes | J40: =IF(Table7[[#This Row],[smoker]]="?","No",Table7[[#This Row],[smoker]]) -> yes | K40: =IFERROR(VALUE(Table7[[#This Row],[NumberOfMajorSurgeries]]),0) -> 0 | L40: =IF(B40 < 18.5, "Underweight", IF(B40 < 25, "Normal Weight", IF(B40 < 30, "Overweight", "Obesity"))) -> Obesity | M40: =IF(C40<5.7,"Normal", IF(C40<6.5,"Prediabetes", IF(C40<7,"Diabetes", "Diabetes"))) -> Diabetes
...

Sheet Hospitalisation Details
A1: Customer ID | B1: year | C1: month | D1: date | E1: children | F1: charges | G1: Hospital tier | H1: City tier | I1: State ID | L1: Year Imputed | M1: Month Imputed | N1: Hospital tier imputer | O1: City tier imputed | P1: State ID Imputed | Q1: Date of Birth | R1: Age
A2: Id2335 | B2: 1992 | C2: Jul | D2: 9 | E2: 0 | F2: 563.84 | G2: tier - 2 | H2: tier - 3 | I2: R1013 | L2: 1992 | M2: Jul | N2: tier - 2 | O2: tier - 3 | P2: R1013 | Q2: =CONCATENATE(Table1[[#This Row],[date]],"-",M2,"-",L2) -> 9-Jul-1992 | R2: =YEARFRAC(Q2,DATE(2023,6,8),1) -> 30.913073 | T2: Year Average | U2: =AVERAGE(Table1[year]) -> 1982.8417
A3: Id2334 | B3: 1992 | C3: Nov | D3: 30 | E3: 0 | F3: 570.62 | G3: tier - 2 | H3: tier - 1 | I3: R1013 | L3: 1992 | M3: Nov | N3: tier - 2 | O3: tier - 1 | P3: R1013 | Q3: =CONCATENATE(Table1[[#This Row],[date]],"-",M3,"-",L3) -> 30-Nov-1992 | R3: =YEARFRAC(Q3,DATE(2023,6,8),1) -> 30.518823 | T3: roundup | U3: 1983
A4: Id2333 | B4: 1993 | C4: Jun | D4: 30 | E4: 0 | F4: 600 | G4: tier - 2 | H4: tier - 1 | I4: R1013 | L4: 1993 | M4: Jun | N4: tier - 2 | O4: tier - 1 | P4: R1013 | Q4: =CONCATENATE(Table1[[#This Row],[date]],"-",M4,"-",L4) -> 30-Jun-1993 | R4: =YEARFRAC(Q4,DATE(2023,6,8),1) -> 29.940382
A5: Id2332 | B5: 1992 | C5: Sep | D5: 13 | E5: 0 | F5: 604.54 | G5: tier - 3 | H5: tier - 3 | I5: R1013 | L5: 1992 | M5: Sep | N5: tier - 3 | O5: tier - 3 | P5: R1013 | Q5: =CONCATENATE(Table1[[#This Row],[date]],"-",M5,"-",L5) -> 13-Sep-1992 | R5: =YEARFRAC(Q5,DATE(2023,6,8),1) -> 30.732375
A6: Id2331 | B6: 1998 | C6: Jul | D6: 27 | E6: 0 | F6: 637.26 | G6: tier - 3 | H6: tier - 3 | I6: R1013 | L6: 1998 | M6: Jul | N6: tier - 3 | O6: tier - 3 | P6: R1013 | Q6: =CONCATENATE(Table1[[#This Row],[date]],"-",M6,"-",L6) -> 27-Jul-1998 | R6: =YEARFRAC(Q6,DATE(2023,6,8),1) -> 24.86647 | T6: City tier | U6: tier - 2
A7: Id2330 | B7: 2001 | C7: Nov | D7: 20 | E7: 0 | F7: 646.14 | G7: tier - 3 | H7: tier - 3 | I7: R1012 | L7: 2001 | M7: Nov | N7: tier - 3 | O7: tier - 3 | P7: R1012 | Q7: =CONCATENATE(Table1[[#This Row],[date]],"-",M7,"-",L7) -> 20-Nov-2001 | R7: =YEARFRAC(Q7,DATE(2023,6,8),1) -> 21.54881 | T7: Hospital tier | U7: 1337 tier - 2
A8: Id2329 | B8: 1993 | C8: Jun | D8: 1 | E8: 0 | F8: 650 | G8: tier - 3 | H8: tier - 3 | I8: R1013 | L8: 1993 | M8: Jun | N8: tier - 3 | O8: tier - 3 | P8: R1013 | Q8: =CONCATENATE(Table1[[#This Row],[date]],"-",M8,"-",L8) -> 1-Jun-1993 | R8: =YEARFRAC(Q8,DATE(2023,6,8),1) -> 30.019784 | T8: smoker | U8: 1845 No
A9: Id2328 | B9: 1995 | C9: Jul | D9: 4 | E9: 0 | F9: 650 | G9: tier - 3 | H9: tier - 3 | I9: R1013 | L9: 1995 | M9: Jul | N9: tier - 3 | O9: tier - 3 | P9: R1013 | Q9: =CONCATENATE(Table1[[#This Row],[date]],"-",M9,"-",L9) -> 4-Jul-1995 | R9: =YEARFRAC(Q9,DATE(2023,6,8),1) -> 27.929475 | T9: State ID | U9: Unknown
A10: Id2327 | B10: 2002 | C10: Nov | D10: 29 | E10: 0 | F10: 668 | G10: tier - 3 | H10: tier - 2 | I10: R1012 | L10: 2002 | M10: Nov | N10: tier - 3 | O10: tier - 2 | P10: R1012 | Q10: =CONCATENATE(Table1[[#This Row],[date]],"-",M10,"-",L10) -> 29-Nov-2002 | R10: =YEARFRAC(Q10,DATE(2023,6,8),1) -> 20.524207
A11: Id2326 | B11: 1997 | C11: Nov | D11: 9 | E11: 0 | F11: 670 | G11: tier - 3 | H11: tier - 3 | I11: R1013 | L11: 1997 | M11: Nov | N11: tier - 3 | O11: tier - 3 | P11: R1013 | Q11: =CONCATENATE(Table1[[#This Row],[date]],"-",M11,"-",L11) -> 9-Nov-1997 | R11: =YEARFRAC(Q11,DATE(2023,6,8),1) -> 25.578947
A12: Id2325 | B12: 2001 | C12: Sep | D12: 12 | E12: 0 | F12: 687.54 | G12: tier - 3 | H12: tier - 2 | I12: R1013 | L12: 2001 | M12: Sep | N12: tier - 3 | O12: tier - 2 | P12: R1013 | Q12: =CONCATENATE(Table1[[#This Row],[date]],"-",M12,"-",L12) -> 12-Sep-2001 | R12: =YEARFRAC(Q12,DATE(2023,6,8),1) -> 21.737738
A13: Id2324 | B13: 1999 | C13: Dec | D13: 26 | E13: 0 | F13: 700 | G13: ? | H13: tier - 3 | I13: R1013 | L13: 1999 | M13: Dec | N13: tier - 2 | O13: tier - 3 | P13: R1013 | Q13: =CONCATENATE(Table1[[#This Row],[date]],"-",M13,"-",L13) -> 26-Dec-1999 | R13: =YEARFRAC(Q13,DATE(2023,6,8),1) -> 23.450334
A14: Id2323 | B14: 1999 | C14: Dec | D14: 14 | E14: 0 | F14: 722.99 | G14: tier - 3 | H14: tier - 1 | I14: R1013 | L14: 1999 | M14: Dec | N14: tier - 3 | O14: tier - 1 | P14: R1013 | Q14: =CONCATENATE(Table1[[#This Row],[date]],"-",M14,"-",L14) -> 14-Dec-1999 | R14: =YEARFRAC(Q14,DATE(2023,6,8),1) -> 23.483189
A15: Id2322 | B15: 2002 | C15: ? | D15: 19 | E15: 0 | F15: 750 | G15: tier - 3 | H15: tier - 1 | I15: R1012 | L15: 2002 | M15: Sep | N15: tier - 3 | O15: tier - 1 | P15: R1012 | Q15: =CONCATENATE(Table1[[#This Row],[date]],"-",M15,"-",L15) -> 19-Sep-2002 | R15: =YEARFRAC(Q15,DATE(2023,6,8),1) -> 20.718606
A16: Id2321 | B16: 1993 | C16: Aug | D16: 9 | E16: 0 | F16: 760 | G16: tier - 3 | H16: tier - 1 | I16: R1013 | L16: 1993 | M16: Aug | N16: tier - 3 | O16: tier - 1 | P16: R1013 | Q16: =CONCATENATE(Table1[[#This Row],[date]],"-",M16,"-",L16) -> 9-Aug-1993 | R16: =YEARFRAC(Q16,DATE(2023,6,8),1) -> 29.83086
A17: Id2320 | B17: 1996 | C17: Oct | D17: 22 | E17: 0 | F17: 760 | G17: tier - 3 | H17: tier - 3 | I17: R1013 | L17: 1996 | M17: Oct | N17: tier - 3 | O17: tier - 3 | P17: R1013 | Q17: =CONCATENATE(Table1[[#This Row],[date]],"-",M17,"-",L17) -> 22-Oct-1996 | R17: =YEARFRAC(Q17,DATE(2023,6,8),1) -> 26.625599
A18: Id2319 | B18: 1993 | C18: Jun | D18: 28 | E18: 0 | F18: 770 | G18: tier - 3 | H18: tier - 3 | I18: R1013 | L18: 1993 | M18: Jun | N18: tier - 3 | O18: tier - 3 | P18: R1013 | Q18: =CONCATENATE(Table1[[#This Row],[date]],"-",M18,"-",L18) -> 28-Jun-1993 | R18: =YEARFRAC(Q18,DATE(2023,6,8),1) -> 29.945858
A19: Id2318 | B19: 1996 | C19: ? | D19: 18 | E19: 0 | F19: 770.38 | G19: tier - 3 | H19: ? | I19: R1012 | L19: 1996 | M19: Sep | N19: tier - 3 | O19: tier - 2 | P19: R1012 | Q19: =CONCATENATE(Table1[[#This Row],[date]],"-",M19,"-",L19) -> 18-Sep-1996 | R19: =YEARFRAC(Q19,DATE(2023,6,8),1) -> 26.718686
A20: Id2317 | B20: 1995 | C20: Dec | D20: 7 | E20: 0 | F20: 773.54 | G20: tier - 3 | H20: tier - 2 | I20: R1013 | L20: 1995 | M20: Dec | N20: tier - 3 | O20: tier - 2 | P20: R1013 | Q20: =CONCATENATE(Table1[[#This Row],[date]],"-",M20,"-",L20) -> 7-Dec-1995 | R20: =YEARFRAC(Q20,DATE(2023,6,8),1) -> 27.50236
A21: Id2316 | B21: 2004 | C21: Oct | D21: 7 | E21: 0 | F21: 830.52 | G21: tier - 3 | H21: tier - 2 | I21: R1011 | L21: 2004 | M21: Oct | N21: tier - 3 | O21: tier - 2 | P21: R1011 | Q21: =CONCATENATE(Table1[[#This Row],[date]],"-",M21,"-",L21) -> 7-Oct-2004 | R21: =YEARFRAC(Q21,DATE(2023,6,8),1) -> 18.666667
... A2344: Id1 | B2344: 1968 | C2344: Oct | D2344: 12 | E2344: 0 | F2344: 63770.43 | G2344: tier - 1 | H2344: tier - 3 | I2344: R1013 | L2344: 1968 | M2344: Oct | N2344: tier - 1 | O2344: tier - 3 | P2344: R1013 | Q2344: =CONCATENATE(Table1[[#This Row],[date]],"-",M2344,"-",L2344) -> 12-Oct-1968 | R2344: =YEARFRAC(Q2344,DATE(2023,6,8),1) -> 54.652977

Sheet Healthacare
A1: Customer ID | B1: First Name | C1: BMI | D1: HBA1C | E1: Heart Issues | F1: Any Transplants | G1: Cancer history | H1: NumberOfMajorSurgeries | I1: Smoker | J1: Weight Status | K1: Diabetes Status | L1: Date of Birth | M1: charges | N1: Hospital tier | O1: City tier | P1: State ID | Q1: Age
A2: Id1 | B2: =VLOOKUP(A2,'Customer Name'!$A$1:$E$2336,4,0) -> Kelly | C2: =VLOOKUP(A2,Table7[#All],2,0) -> 47.41 | D2: =VLOOKUP(A2,Table7[#All],3,0) -> 7.47 | E2: =VLOOKUP(A2,Table7[#All],4,0) -> No | F2: =VLOOKUP(A2,Table7[#All],5,0) -> No | G2: =VLOOKUP(A2,Table7[#All],6,0) -> No | H2: =VLOOKUP(A2,'Medical Examination'!A1:M2336,11,0) -> 0 | I2: =VLOOKUP(A2,'Medical Examination'!A1:M2336,10,0) -> yes | J2: =VLOOKUP(A2,'Medical Examination'!A1:M2336,12,0) -> Obesity | K2: =VLOOKUP(A2,'Medical Examination'!A1:M2336,13,0) -> Diabetes | L2: =VLOOKUP(A2,'Hospitalisation Details'!A1:R2344,17,0) -> 12-Oct-1968 | M2: =VLOOKUP(A2,'Hospitalisation Details'!$A$1:$R$2344,6,0) -> 63770.43 | N2: =VLOOKUP(A2,'Hospitalisation Details'!$A$1:$R$2344,14,0) -> tier - 1 | O2: =VLOOKUP(A2,'Hospitalisation Details'!$A$1:$R$2344,15,0) -> tier - 3 | P2: =VLOOKUP(A2,'Hospitalisation Details'!$A$1:$R$2344,16,0) -> R1013 | Q2: =VLOOKUP(A2,'Hospitalisation Details'!A1:R2344,18,0) -> 54.652977
A3: Id2 | B3: =VLOOKUP(A3,'Customer Name'!A2:E2337,4,0) -> Matthew D | C3: =VLOOKUP(A3,Table7[#All],2,0) -> 30.36 | D3: =VLOOKUP(A3,Table7[#All],3,0) -> 5.77 | E3: =VLOOKUP(A3,Table7[#All],4,0) -> No | F3: =VLOOKUP(A3,Table7[#All],5,0) -> No | G3: =VLOOKUP(A3,Table7[#All],6,0) -> No | H3: =VLOOKUP(A3,'Medical Examination'!A2:M2337,11,0) -> 0 | I3: =VLOOKUP(A3,'Medical Examination'!A2:M2337,10,0) -> yes | J3: =VLOOKUP(A3,'Medical Examination'!A2:M2337,12,0) -> Obesity | K3: =VLOOKUP(A3,'Medical Examination'!A2:M2337,13,0) -> Prediabetes | L3: =VLOOKUP(A3,'Hospitalisation Details'!A2:R2345,17,0) -> 8-Jun-1977 | M3: =VLOOKUP(A3,'Hospitalisation Details'!$A$1:$R$2344,6,0) -> 62592.87 | N3: =VLOOKUP(A3,'Hospitalisation Details'!$A$1:$R$2344,14,0) -> tier - 2 | O3: =VLOOKUP(A3,'Hospitalisation Details'!$A$1:$R$2344,15,0) -> tier - 3 | P3: =VLOOKUP(A3,'Hospitalisation Details'!$A$1:$R$2344,16,0) -> R1013 | Q3: =VLOOKUP(A3,'Hospitalisation Details'!A2:R2345,18,0) -> 46.000641
A4: Id3 | B4: =VLOOKUP(A4,'Customer Name'!A3:E2338,4,0) -> Phil | C4: =VLOOKUP(A4,Table7[#All],2,0) -> 34.485 | D4: =VLOOKUP(A4,Table7[#All],3,0) -> 11.87 | E4: =VLOOKUP(A4,Table7[#All],4,0) -> yes | F4: =VLOOKUP(A4,Table7[#All],5,0) -> No | G4: =VLOOKUP(A4,Table7[#All],6,0) -> No | H4: =VLOOKUP(A4,'Medical Examination'!A3:M2338,11,0) -> 2 | I4: =VLOOKUP(A4,'Medical Examination'!A3:M2338,10,0) -> yes | J4: =VLOOKUP(A4,'Medical Examination'!A3:M2338,12,0) -> Obesity | K4: =VLOOKUP(A4,'Medical Examination'!A3:M2338,13,0) -> Diabetes | L4: =VLOOKUP(A4,'Hospitalisation Details'!A3:R2346,17,0) -> 11-Sep-1970 | M4: =VLOOKUP(A4,'Hospitalisation Details'!$A$1:$R$2344,6,0) -> 60021.4 | N4: =VLOOKUP(A4,'Hospitalisation Details'!$A$1:$R$2344,14,0) -> tier - 1 | O4: =VLOOKUP(A4,'Hospitalisation Details'!$A$1:$R$2344,15,0) -> tier - 1 | P4: =VLOOKUP(A4,'Hospitalisation Details'!$A$1:$R$2344,16,0) -> R1012 | Q4: =VLOOKUP(A4,'Hospitalisation Details'!A3:R2346,18,0) -> 52.740557
A5: Id4 | B5: =VLOOKUP(A5,'Customer Name'!A4:E2339,4,0) -> Kelsey | C5: =VLOOKUP(A5,Table7[#All],2,0) -> 38.095 | D5: =VLOOKUP(A5,Table7[#All],3,0) -> 6.05 | E5: =VLOOKUP(A5,Table7[#All],4,0) -> No | F5: =VLOOKUP(A5,Table7[#All],5,0) -> No | G5: =VLOOKUP(A5,Table7[#All],6,0) -> No | H5: =VLOOKUP(A5,'Medical Examination'!A4:M2339,11,0) -> 0 | I5: =VLOOKUP(A5,'Medical Examination'!A4:M2339,10,0) -> yes | J5: =VLOOKUP(A5,'Medical Examination'!A4:M2339,12,0) -> Obesity | K5: =VLOOKUP(A5,'Medical Examination'!A4:M2339,13,0) -> Prediabetes | L5: =VLOOKUP(A5,'Hospitalisation Details'!A4:R2347,17,0) -> 6-Jun-1991 | M5: =VLOOKUP(A5,'Hospitalisation Details'!$A$1:$R$2344,6,0) -> 58571.07 | N5: =VLOOKUP(A5,'Hospitalisation Details'!$A$1:$R$2344,14,0) -> tier - 1 | O5: =VLOOKUP(A5,'Hospitalisation Details'!$A$1:$R$2344,15,0) -> tier - 3 | P5: =VLOOKUP(A5,'Hospitalisation Details'!$A$1:$R$2344,16,0) -> R1024 | Q5: =VLOOKUP(A5,'Hospitalisation Details'!A4:R2347,18,0) -> 32.00614
A6: Id5 | B6: =VLOOKUP(A6,'Customer Name'!A5:E2340,4,0) -> Kristyn | C6: =VLOOKUP(A6,Table7[#All],2,0) -> 35.53 | D6: =VLOOKUP(A6,Table7[#All],3,0) -> 5.45 | E6: =VLOOKUP(A6,Table7[#All],4,0) -> No | F6: =VLOOKUP(A6,Table7[#All],5,0) -> No | G6: =VLOOKUP(A6,Table7[#All],6,0) -> No | H6: =VLOOKUP(A6,'Medical Examination'!A5:M2340,11,0) -> 0 | I6: =VLOOKUP(A6,'Medical Examination'!A5:M2340,10,0) -> yes | J6: =VLOOKUP(A6,'Medical Examination'!A5:M2340,12,0) -> Obesity | K6: =VLOOKUP(A6,'Medical Examination'!A5:M2340,13,0) -> Normal | L6: =VLOOKUP(A6,'Hospitalisation Details'!A5:R2348,17,0) -> 19-Jun-1989 | M6: =VLOOKUP(A6,'Hospitalisation Details'!$A$1:$R$2344,6,0) -> 55135.4 | N6: =VLOOKUP(A6,'Hospitalisation Details'!$A$1:$R$2344,14,0) -> tier - 1 | O6: =VLOOKUP(A6,'Hospitalisation Details'!$A$1:$R$2344,15,0) -> tier - 2 | P6: =VLOOKUP(A6,'Hospitalisation Details'!$A$1:$R$2344,16,0) -> R1012 | Q6: =VLOOKUP(A6,'Hospitalisation Details'!A5:R2348,18,0) -> 33.970508 | S6: Combined Data
A7: Id6 | B7: =VLOOKUP(A7,'Customer Name'!A6:E2341,4,0) -> Russell B. | C7: =VLOOKUP(A7,Table7[#All],2,0) -> 32.8 | D7: =VLOOKUP(A7,Table7[#All],3,0) -> 6.59 | E7: =VLOOKUP(A7,Table7[#All],4,0) -> No | F7: =VLOOKUP(A7,Table7[#All],5,0) -> No | G7: =VLOOKUP(A7,Table7[#All],6,0) -> No | H7: =VLOOKUP(A7,'Medical Examination'!A6:M2341,11,0) -> 0 | I7: =VLOOKUP(A7,'Medical Examination'!A6:M2341,10,0) -> yes | J7: =VLOOKUP(A7,'Medical Examination'!A6:M2341,12,0) -> Obesity | K7: =VLOOKUP(A7,'Medical Examination'!A6:M2341,13,0) -> Diabetes | L7: =VLOOKUP(A7,'Hospitalisation Details'!A6:R2349,17,0) -> 4-Aug-1962 | M7: =VLOOKUP(A7,'Hospitalisation Details'!$A$1:$R$2344,6,0) -> 52590.83 | N7: =VLOOKUP(A7,'Hospitalisation Details'!$A$1:$R$2344,14,0) -> tier - 1 | O7: =VLOOKUP(A7,'Hospitalisation Details'!$A$1:$R$2344,15,0) -> tier - 3 | P7: =VLOOKUP(A7,'Hospitalisation Details'!$A$1:$R$2344,16,0) -> R1011 | Q7: =VLOOKUP(A7,'Hospitalisation Details'!A6:R2349,18,0) -> 60.844601
A8: Id7 | B8: =VLOOKUP(A8,'Customer Name'!A7:E2342,4,0) -> Scott | C8: =VLOOKUP(A8,Table7[#All],2,0) -> 36.4 | D8: =VLOOKUP(A8,Table7[#All],3,0) -> 6.07 | E8: =VLOOKUP(A8,Table7[#All],4,0) -> No | F8: =VLOOKUP(A8,Table7[#All],5,0) -> No | G8: =VLOOKUP(A8,Table7[#All],6,0) -> No | H8: =VLOOKUP(A8,'Medical Examination'!A7:M2342,11,0) -> 0 | I8: =VLOOKUP(A8,'Medical Examination'!A7:M2342,10,0) -> yes | J8: =VLOOKUP(A8,'Medical Examination'!A7:M2342,12,0) -> Obesity | K8: =VLOOKUP(A8,'Medical Examination'!A7:M2342,13,0) -> Prediabetes | L8: =VLOOKUP(A8,'Hospitalisation Details'!A7:R2350,17,0) -> 27-Oct-1994 | M8: =VLOOKUP(A8,'Hospitalisation Details'!$A$1:$R$2344,6,0) -> 51194.56 | N8: =VLOOKUP(A8,'Hospitalisation Details'!$A$1:$R$2344,14,0) -> tier - 1 | O8: =VLOOKUP(A8,'Hospitalisation Details'!$A$1:$R$2344,15,0) -> tier - 3 | P8: =VLOOKUP(A8,'Hospitalisation Details'!$A$1:$R$2344,16,0) -> R1011 | Q8: =VLOOKUP(A8,'Hospitalisation Details'!A7:R2350,18,0) -> 28.614584
A9: Id8 | B9: =VLOOKUP(A9,'Customer Name'!A8:E2343,4,0) -> Stephen | C9: =VLOOKUP(A9,Table7[#All],2,0) -> 36.96 | D9: =VLOOKUP(A9,Table7[#All],3,0) -> 7.93 | E9: =VLOOKUP(A9,Table7[#All],4,0) -> No | F9: =VLOOKUP(A9,Table7[#All],5,0) -> No | G9: =VLOOKUP(A9,Table7[#All],6,0) -> No | H9: =VLOOKUP(A9,'Medical Examination'!A8:M2343,11,0) -> 3 | I9: =VLOOKUP(A9,'Medical Examination'!A8:M2343,10,0) -> yes | J9: =VLOOKUP(A9,'Medical Examination'!A8:M2343,12,0) -> Obesity | K9: =VLOOKUP(A9,'Medical Examination'!A8:M2343,13,0) -> Diabetes | L9: =VLOOKUP(A9,'Hospitalisation Details'!A8:R2351,17,0) -> 27-Jun-1958 | M9: =VLOOKUP(A9,'Hospitalisation Details'!$A$1:$R$2344,6,0) -> 49577.66 | N9: =VLOOKUP(A9,'Hospitalisation Details'!$A$1:$R$2344,14,0) -> tier - 2 | O9: =VLOOKUP(A9,'Hospitalisation Details'!$A$1:$R$2344,15,0) -> tier - 2 | P9: =VLOOKUP(A9,'Hospitalisation Details'!$A$1:$R$2344,16,0) -> R1013 | Q9: =VLOOKUP(A9,'Hospitalisation Details'!A8:R2351,18,0) -> 64.948643
A10: Id9 | B10: =VLOOKUP(A10,'Customer Name'!A9:E2344,4,0) -> Patrick R. | C10: =VLOOKUP(A10,Table7[#All],2,0) -> 41.14 | D10: =VLOOKUP(A10,Table7[#All],3,0) -> 9.58 | E10: =VLOOKUP(A10,Table7[#All],4,0) -> yes | F10: =VLOOKUP(A10,Table7[#All],5,0) -> No | G10: =VLOOKUP(A10,Table7[#All],6,0) -> Yes | H10: =VLOOKUP(A10,'Medical Examination'!A9:M2344,11,0) -> 1 | I10: =VLOOKUP(A10,'Medical Examination'!A9:M2344,10,0) -> yes | J10: =VLOOKUP(A10,'Medical Examination'!A9:M2344,12,0) -> Obesity | K10: =VLOOKUP(A10,'Medical Examination'!A9:M2344,13,0) -> Diabetes | L10: =VLOOKUP(A10,'Hospitalisation Details'!A9:R2352,17,0) -> 4-Sep-1963 | M10: =VLOOKUP(A10,'Hospitalisation Details'!$A$1:$R$2344,6,0) -> 48970.25 | N10: =VLOOKUP(A10,'Hospitalisation Details'!$A$1:$R$2344,14,0) -> tier - 1 | O10: =VLOOKUP(A10,'Hospitalisation Details'!$A$1:$R$2344,15,0) -> tier - 2 | P10: =VLOOKUP(A10,'Hospitalisation Details'!$A$1:$R$2344,16,0) -> R1013 | Q10: =VLOOKUP(A10,'Hospitalisation Details'!A9:R2352,18,0) -> 59.75974
A11: Id10 | B11: =VLOOKUP(A11,'Customer Name'!A10:E2345,4,0) -> Brooke N. | C11: =VLOOKUP(A11,Table7[#All],2,0) -> 38.06 | D11: =VLOOKUP(A11,Table7[#All],3,0) -> 10.79 | E11: =VLOOKUP(A11,Table7[#All],4,0) -> No | F11: =VLOOKUP(A11,Table7[#All],5,0) -> No | G11: =VLOOKUP(A11,Table7[#All],6,0) -> No | H11: =VLOOKUP(A11,'Medical Examination'!A10:M2345,11,0) -> 0 | I11: =VLOOKUP(A11,'Medical Examination'!A10:M2345,10,0) -> yes | J11: =VLOOKUP(A11,'Medical Examination'!A10:M2345,12,0) -> Obesity | K11: =VLOOKUP(A11,'Medical Examination'!A10:M2345,13,0) -> Diabetes | L11: =VLOOKUP(A11,'Hospitalisation Details'!A10:R2353,17,0) -> 29-Dec-1978 | M11: =VLOOKUP(A11,'Hospitalisation Details'!$A$1:$R$2344,6,0) -> 48885.14 | N11: =VLOOKUP(A11,'Hospitalisation Details'!$A$1:$R$2344,14,0) -> tier - 1 | O11: =VLOOKUP(A11,'Hospitalisation Details'!$A$1:$R$2344,15,0) -> tier - 2 | P11: =VLOOKUP(A11,'Hospitalisation Details'!$A$1:$R$2344,16,0) -> R1013 | Q11: =VLOOKUP(A11,'Hospitalisation Details'!A10:R2353,18,0) -> 44.442117
A12: Id11 | B12: =VLOOKUP(A12,'Customer Name'!A11:E2346,4,0) -> Paola Andrea | C12: =VLOOKUP(A12,Table7[#All],2,0) -> 37.7 | D12: =VLOOKUP(A12,Table7[#All],3,0) -> 5.96 | E12: =VLOOKUP(A12,Table7[#All],4,0) -> yes | F12: =VLOOKUP(A12,Table7[#All],5,0) -> No | G12: =VLOOKUP(A12,Table7[#All],6,0) -> No | H12: =VLOOKUP(A12,'Medical Examination'!A11:M2346,11,0) -> 2 | I12: =VLOOKUP(A12,'Medical Examination'!A11:M2346,10,0) -> yes | J12: =VLOOKUP(A12,'Medical Examination'!A11:M2346,12,0) -> Obesity | K12: =VLOOKUP(A12,'Medical Examination'!A11:M2346,13,0) -> Prediabetes | L12: =VLOOKUP(A12,'Hospitalisation Details'!A11:R2354,17,0) -> 22-Jul-1959 | M12: =VLOOKUP(A12,'Hospitalisation Details'!$A$1:$R$2344,6,0) -> 48824.45 | N12: =VLOOKUP(A12,'Hospitalisation Details'!$A$1:$R$2344,14,0) -> tier - 2 | O12: =VLOOKUP(A12,'Hospitalisation Details'!$A$1:$R$2344,15,0) -> tier - 1 | P12: =VLOOKUP(A12,'Hospitalisation Details'!$A$1:$R$2344,16,0) -> R1011 | Q12: =VLOOKUP(A12,'Hospitalisation Details'!A11:R2354,18,0) -> 63.880207
A13: Id12 | B13: =VLOOKUP(A13,'Customer Name'!A12:E2347,4,0) -> David | C13: =VLOOKUP(A13,Table7[#All],2,0) -> 42.13 | D13: =VLOOKUP(A13,Table7[#All],3,0) -> 11.9 | E13: =VLOOKUP(A13,Table7[#All],4,0) -> No | F13: =VLOOKUP(A13,Table7[#All],5,0) -> No | G13: =VLOOKUP(A13,Table7[#All],6,0) -> No | H13: =VLOOKUP(A13,'Medical Examination'!A12:M2347,11,0) -> 0 | I13: =VLOOKUP(A13,'Medical Examination'!A12:M2347,10,0) -> yes | J13: =VLOOKUP(A13,'Medical Examination'!A12:M2347,12,0) -> Obesity | K13: =VLOOKUP(A13,'Medical Examination'!A12:M2347,13,0) -> Diabetes | L13: =VLOOKUP(A13,'Hospitalisation Details'!A12:R2355,17,0) -> 27-Oct-1965 | M13: =VLOOKUP(A13,'Hospitalisation Details'!$A$1:$R$2344,6,0) -> 48675.52 | N13: =VLOOKUP(A13,'Hospitalisation Details'!$A$1:$R$2344,14,0) -> tier - 1 | O13: =VLOOKUP(A13,'Hospitalisation Details'!$A$1:$R$2344,15,0) -> tier - 2 | P13: =VLOOKUP(A13,'Hospitalisation Details'!$A$1:$R$2344,16,0) -> R1013 | Q13: =VLOOKUP(A13,'Hospitalisation Details'!A12:R2355,18,0) -> 57.614599
A14: Id13 | B14: =VLOOKUP(A14,'Customer Name'!A13:E2348,4,0) -> Wade | C14: =VLOOKUP(A14,Table7[#All],2,0) -> 40.92 | D14: =VLOOKUP(A14,Table7[#All],3,0) -> 8.41 | E14: =VLOOKUP(A14,Table7[#All],4,0) -> No | F14: =VLOOKUP(A14,Table7[#All],5,0) -> No | G14: =VLOOKUP(A14,Table7[#All],6,0) -> No | H14: =VLOOKUP(A14,'Medical Examination'!A13:M2348,11,0) -> 0 | I14: =VLOOKUP(A14,'Medical Examination'!A13:M2348,10,0) -> yes | J14: =VLOOKUP(A14,'Medical Examination'!A13:M2348,12,0) -> Obesity | K14: =VLOOKUP(A14,'Medical Examination'!A13:M2348,13,0) -> Diabetes | L14: =VLOOKUP(A14,'Hospitalisation Details'!A13:R2356,17,0) -> 11-Oct-1962 | M14: =VLOOKUP(A14,'Hospitalisation Details'!$A$1:$R$2344,6,0) -> 48673.56 | N14: =VLOOKUP(A14,'Hospitalisation Details'!$A$1:$R$2344,14,0) -> tier - 1 | O14: =VLOOKUP(A14,'Hospitalisation Details'!$A$1:$R$2344,15,0) -> tier - 2 | P14: =VLOOKUP(A14,'Hospitalisation Details'!$A$1:$R$2344,16,0) -> R1013 | Q14: =VLOOKUP(A14,'Hospitalisation Details'!A13:R2356,18,0) -> 60.658423
A15: Id14 | B15: =VLOOKUP(A15,'Customer Name'!A14:E2349,4,0) -> Franklin | C15: =VLOOKUP(A15,Table7[#All],2,0) -> 40.565 | D15: =VLOOKUP(A15,Table7[#All],3,0) -> 7.02 | E15: =VLOOKUP(A15,Table7[#All],4,0) -> No | F15: =VLOOKUP(A15,Table7[#All],5,0) -> No | G15: =VLOOKUP(A15,Table7[#All],6,0) -> No | H15: =VLOOKUP(A15,'Medical Examination'!A14:M2349,11,0) -> 0 | I15: =VLOOKUP(A15,'Medical Examination'!A14:M2349,10,0) -> yes | J15: =VLOOKUP(A15,'Medical Examination'!A14:M2349,12,0) -> Obesity | K15: =VLOOKUP(A15,'Medical Examination'!A14:M2349,13,0) -> Diabetes | L15: =VLOOKUP(A15,'Hospitalisation Details'!A14:R2357,17,0) -> 1-Dec-1968 | M15: =VLOOKUP(A15,'Hospitalisation Details'!$A$1:$R$2344,6,0) -> 48549.18 | N15: =VLOOKUP(A15,'Hospitalisation Details'!$A$1:$R$2344,14,0) -> tier - 1 | O15: =VLOOKUP(A15,'Hospitalisation Details'!$A$1:$R$2344,15,0) -> tier - 3 | P15: =VLOOKUP(A15,'Hospitalisation Details'!$A$1:$R$2344,16,0) -> R1016 | Q15: =VLOOKUP(A15,'Hospitalisation Details'!A14:R2357,18,0) -> 54.516085
A16: Id15 | B16: =VLOOKUP(A16,'Customer Name'!A15:E2350,4,0) -> Leilani M. | C16: =VLOOKUP(A16,Table7[#All],2,0) -> 36.385 | D16: =VLOOKUP(A16,Table7[#All],3,0) -> 7.59 | E16: =VLOOKUP(A16,Table7[#All],4,0) -> yes | F16: =VLOOKUP(A16,Table7[#All],5,0) -> No | G16: =VLOOKUP(A16,Table7[#All],6,0) -> No | H16: =VLOOKUP(A16,'Medical Examination'!A15:M2350,11,0) -> 2 | I16: =VLOOKUP(A16,'Medical Examination'!A15:M2350,10,0) -> yes | J16: =VLOOKUP(A16,'Medical Examination'!A15:M2350,12,0) -> Obesity | K16: =VLOOKUP(A16,'Medical Examination'!A15:M2350,13,0) -> Diabetes | L16: =VLOOKUP(A16,'Hospitalisation Details'!A15:R2358,17,0) -> 21-Dec-1961 | M16: =VLOOKUP(A16,'Hospitalisation Details'!$A$1:$R$2344,6,0) -> 48517.56 | N16: =VLOOKUP(A16,'Hospitalisation Details'!$A$1:$R$2344,14,0) -> tier - 1 | O16: =VLOOKUP(A16,'Hospitalisation Details'!$A$1:$R$2344,15,0) -> tier - 3 | P16: =VLOOKUP(A16,'Hospitalisation Details'!$A$1:$R$2344,16,0) -> R1024 | Q16: =VLOOKUP(A16,'Hospitalisation Details'!A15:R2358,18,0) -> 61.464016
A17: Id16 | B17: =VLOOKUP(A17,'Customer Name'!A16:E2351,4,0) -> Philippe | C17: =VLOOKUP(A17,Table7[#All],2,0) -> 39.9 | D17: =VLOOKUP(A17,Table7[#All],3,0) -> 11.32 | E17: =VLOOKUP(A17,Table7[#All],4,0) -> No | F17: =VLOOKUP(A17,Table7[#All],5,0) -> No | G17: =VLOOKUP(A17,Table7[#All],6,0) -> No | H17: =VLOOKUP(A17,'Medical Examination'!A16:M2351,11,0) -> 0 | I17: =VLOOKUP(A17,'Medical Examination'!A16:M2351,10,0) -> yes | J17: =VLOOKUP(A17,'Medical Examination'!A16:M2351,12,0) -> Obesity | K17: =VLOOKUP(A17,'Medical Examination'!A16:M2351,13,0) -> Diabetes | L17: =VLOOKUP(A17,'Hospitalisation Details'!A16:R2359,17,0) -> 27-Aug-1962 | M17: =VLOOKUP(A17,'Hospitalisation Details'!$A$1:$R$2344,6,0) -> 48173.36 | N17: =VLOOKUP(A17,'Hospitalisation Details'!$A$1:$R$2344,14,0) -> tier - 1 | O17: =VLOOKUP(A17,'Hospitalisation Details'!$A$1:$R$2344,15,0) -> tier - 3 | P17: =VLOOKUP(A17,'Hospitalisation Details'!$A$1:$R$2344,16,0) -> R1011 | Q17: =VLOOKUP(A17,'Hospitalisation Details'!A16:R2359,18,0) -> 60.781629
A18: Id17 | B18: =VLOOKUP(A18,'Customer Name'!A17:E2352,4,0) -> Jennifer A. | C18: =VLOOKUP(A18,Table7[#All],2,0) -> 33.8 | D18: =VLOOKUP(A18,Table7[#All],3,0) -> 7.67 | E18: =VLOOKUP(A18,Table7[#All],4,0) -> No | F18: =VLOOKUP(A18,Table7[#All],5,0) -> No | G18: =VLOOKUP(A18,Table7[#All],6,0) -> No | H18: =VLOOKUP(A18,'Medical Examination'!A17:M2352,11,0) -> 3 | I18: =VLOOKUP(A18,'Medical Examination'!A17:M2352,10,0) -> yes | J18: =VLOOKUP(A18,'Medical Examination'!A17:M2352,12,0) -> Obesity | K18: =VLOOKUP(A18,'Medical Examination'!A17:M2352,13,0) -> Diabetes | L18: =VLOOKUP(A18,'Hospitalisation Details'!A17:R2360,17,0) -> 16-Nov-1958 | M18: =VLOOKUP(A18,'Hospitalisation Details'!$A$1:$R$2344,6,0) -> 47928.03 | N18: =VLOOKUP(A18,'Hospitalisation Details'!$A$1:$R$2344,14,0) -> tier - 2 | O18: =VLOOKUP(A18,'Hospitalisation Details'!$A$1:$R$2344,15,0) -> tier - 3 | P18: =VLOOKUP(A18,'Hospitalisation Details'!$A$1:$R$2344,16,0) -> R1011 | Q18: =VLOOKUP(A18,'Hospitalisation Details'!A17:R2360,18,0) -> 64.559861
... A1171: Id1170 | B1171: =VLOOKUP(A1171,'Customer Name'!A1170:E3505,4,0) -> Grant | C1171: =VLOOKUP(A1171,Table7[#All],2,0) -> 28.61 | D1171: =VLOOKUP(A1171,Table7[#All],3,0) -> 5.76 | E1171: =VLOOKUP(A1171,Table7[#All],4,0) -> No | F1171: =VLOOKUP(A1171,Table7[#All],5,0) -> No | G1171: =VLOOKUP(A1171,Table7[#All],6,0) -> Yes | H1171: =VLOOKUP(A1171,'Medical Examination'!A1170:M3505,11,0) -> 1 | I1171: =VLOOKUP(A1171,'Medical Examination'!A1170:M3505,10,0) -> No | J1171: =VLOOKUP(A1171,'Medical Examination'!A1170:M3505,12,0) -> Overweight | K1171: =VLOOKUP(A1171,'Medical Examination'!A1170:M3505,13,0) -> Prediabetes | L1171: =VLOOKUP(A1171,'Hospitalisation Details'!A1170:R3513,17,0) -> 19-Dec-1979 | M1171: =VLOOKUP(A1171,'Hospitalisation Details'!$A$1:$R$2344,6,0) -> 9630.3 | N1171: =VLOOKUP(A1171,'Hospitalisation Details'!$A$1:$R$2344,14,0) -> tier - 2 | O1171: =VLOOKUP(A1171,'Hospitalisation Details'!$A$1:$R$2344,15,0) -> tier - 2 | P1171: =VLOOKUP(A1171,'Hospitalisation Details'!$A$1:$R$2344,16,0) -> R1021 | Q1171: =VLOOKUP(A1171,'Hospitalisation Details'!A1170:R3513,18,0) -> 43.469518
A1172: Id1171 | B1172: =VLOOKUP(A1172,'Customer Name'!A1171:E3506,4,0) -> . Sophia | C1172: =VLOOKUP(A1172,Table7[#All],2,0) -> 45.41 | D1172: =VLOOKUP(A1172,Table7[#All],3,0) -> 4.96 | E1172: =VLOOKUP(A1172,Table7[#All],4,0) -> No | F1172: =VLOOKUP(A1172,Table7[#All],5,0) -> No | G1172: =VLOOKUP(A1172,Table7[#All],6,0) -> No | H1172: =VLOOKUP(A1172,'Medical Examination'!A1171:M3506,11,0) -> 1 | I1172: =VLOOKUP(A1172,'Medical Examination'!A1171:M3506,10,0) -> No | J1172: =VLOOKUP(A1172,'Medical Examination'!A1171:M3506,12,0) -> Obesity | K1172: =VLOOKUP(A1172,'Medical Examination'!A1171:M3506,13,0) -> Normal | L1172: =VLOOKUP(A1172,'Hospitalisation Details'!A1:R2344,17,0) -> 23-Jun-1998 | M1172: =VLOOKUP(A1172,'Hospitalisation Details'!$A$1:$R$2344,6,0) -> 9628.79 | N1172: =VLOOKUP(A1172,'Hospitalisation Details'!$A$1:$R$2344,14,0) -> tier - 2 | O1172: =VLOOKUP(A1172,'Hospitalisation Details'!$A$1:$R$2344,15,0) -> tier - 2 | P1172: =VLOOKUP(A1172,'Hospitalisation Details'!$A$1:$R$2344,16,0) -> R1026 | Q1172: =VLOOKUP(A1172,'Hospitalisation Details'!$A$1:$R$2344,18,0) -> 24.959562
A1173: Id1172 | B1173: =VLOOKUP(A1173,'Customer Name'!A1172:E3507,4,0) -> Christina | C1173: =VLOOKUP(A1173,Table7[#All],2,0) -> 31.2 | D1173: =VLOOKUP(A1173,Table7[#All],3,0) -> 11.04 | E1173: =VLOOKUP(A1173,Table7[#All],4,0) -> yes | F1173: =VLOOKUP(A1173,Table7[#All],5,0) -> No | G1173: =VLOOKUP(A1173,Table7[#All],6,0) -> No | H1173: =VLOOKUP(A1173,'Medical Examination'!A1172:M3507,11,0) -> 2 | I1173: =VLOOKUP(A1173,'Medical Examination'!A1172:M3507,10,0) -> No | J1173: =VLOOKUP(A1173,'Medical Examination'!A1172:M3507,12,0) -> Obesity | K1173: =VLOOKUP(A1173,'Medical Examination'!A1172:M3507,13,0) -> Diabetes | L1173: =VLOOKUP(A1173,'Hospitalisation Details'!A2:R2345,17,0) -> 16-Dec-1970 | M1173: =VLOOKUP(A1173,'Hospitalisation Details'!$A$1:$R$2344,6,0) -> 9625.92 | N1173: =VLOOKUP(A1173,'Hospitalisation Details'!$A$1:$R$2344,14,0) -> tier - 2 | O1173: =VLOOKUP(A1173,'Hospitalisation Details'!$A$1:$R$2344,15,0) -> tier - 3 | P1173: =VLOOKUP(A1173,'Hospitalisation Details'!$A$1:$R$2344,16,0) -> R1011 | Q1173: =VLOOKUP(A1173,'Hospitalisation Details'!$A$1:$R$2344,18,0) -> 52.477716
A1174: Id1173 | B1174: =VLOOKUP(A1174,'Customer Name'!A1173:E3508,4,0) -> Sam L. | C1174: =VLOOKUP(A1174,Table7[#All],2,0) -> 29.83 | D1174: =VLOOKUP(A1174,Table7[#All],3,0) -> 7.81 | E1174: =VLOOKUP(A1174,Table7[#All],4,0) -> yes | F1174: =VLOOKUP(A1174,Table7[#All],5,0) -> No | G1174: =VLOOKUP(A1174,Table7[#All],6,0) -> No | H1174: =VLOOKUP(A1174,'Medical Examination'!A1173:M3508,11,0) -> 1 | I1174: =VLOOKUP(A1174,'Medical Examination'!A1173:M3508,10,0) -> No | J1174: =VLOOKUP(A1174,'Medical Examination'!A1173:M3508,12,0) -> Overweight | K1174: =VLOOKUP(A1174,'Medical Examination'!A1173:M3508,13,0) -> Diabetes | L1174: =VLOOKUP(A1174,'Hospitalisation Details'!A3:R2346,17,0) -> 29-Oct-1975 | M1174: =VLOOKUP(A1174,'Hospitalisation Details'!$A$1:$R$2344,6,0) -> 9620.33 | N1174: =VLOOKUP(A1174,'Hospitalisation Details'!$A$1:$R$2344,14,0) -> tier - 3 | O1174: =VLOOKUP(A1174,'Hospitalisation Details'!$A$1:$R$2344,15,0) -> tier - 3 | P1174: =VLOOKUP(A1174,'Hospitalisation Details'!$A$1:$R$2344,16,0) -> R1012 | Q1174: =VLOOKUP(A1174,'Hospitalisation Details'!$A$1:$R$2344,18,0) -> 47.609152
A1175: Id1174 | B1175: =VLOOKUP(A1175,'Customer Name'!A1174:E3509,4,0) -> . Haley R. | C1175: =VLOOKUP(A1175,Table7[#All],2,0) -> 29.06 | D1175: =VLOOKUP(A1175,Table7[#All],3,0) -> 4.55 | E1175: =VLOOKUP(A1175,Table7[#All],4,0) -> No | F1175: =VLOOKUP(A1175,Table7[#All],5,0) -> No | G1175: =VLOOKUP(A1175,Table7[#All],6,0) -> No | H1175: =VLOOKUP(A1175,'Medical Examination'!A1174:M3509,11,0) -> 0 | I1175: =VLOOKUP(A1175,'Medical Examination'!A1174:M3509,10,0) -> No | J1175: =VLOOKUP(A1175,'Medical Examination'!A1174:M3509,12,0) -> Overweight | K1175: =VLOOKUP(A1175,'Medical Examination'!A1174:M3509,13,0) -> Normal | L1175: =VLOOKUP(A1175,'Hospitalisation Details'!A4:R2347,17,0) -> 29-Aug-1982 | M1175: =VLOOKUP(A1175,'Hospitalisation Details'!$A$1:$R$2344,6,0) -> 9619.18 | N1175: =VLOOKUP(A1175,'Hospitalisation Details'!$A$1:$R$2344,14,0) -> tier - 2 | O1175: =VLOOKUP(A1175,'Hospitalisation Details'!$A$1:$R$2344,15,0) -> tier - 1 | P1175: =VLOOKUP(A1175,'Hospitalisation Details'!$A$1:$R$2344,16,0) -> R1025 | Q1175: =VLOOKUP(A1175,'Hospitalisation Details'!$A$1:$R$2344,18,0) -> 40.776141
A1176: Id1175 | B1176: =VLOOKUP(A1176,'Customer Name'!A1175:E3510,4,0) -> Ethan | C1176: =VLOOKUP(A1176,Table7[#All],2,0) -> 27.455 | D1176: =VLOOKUP(A1176,Table7[#All],3,0) -> 6.13 | E1176: =VLOOKUP(A1176,Table7[#All],4,0) -> No | F1176: =VLOOKUP(A1176,Table7[#All],5,0) -> No | G1176: =VLOOKUP(A1176,Table7[#All],6,0) -> No | H1176: =VLOOKUP(A1176,'Medical Examination'!A1175:M3510,11,0) -> 2 | I1176: =VLOOKUP(A1176,'Medical Examination'!A1175:M3510,10,0) -> No | J1176: =VLOOKUP(A1176,'Medical Examination'!A1175:M3510,12,0) -> Overweight | K1176: =VLOOKUP(A1176,'Medical Examination'!A1175:M3510,13,0) -> Prediabetes | L1176: =VLOOKUP(A1176,'Hospitalisation Details'!A5:R2348,17,0) -> 27-Dec-1972 | M1176: =VLOOKUP(A1176,'Hospitalisation Details'!$A$1:$R$2344,6,0) -> 9617.66 | N1176: =VLOOKUP(A1176,'Hospitalisation Details'!$A$1:$R$2344,14,0) -> tier - 3 | O1176: =VLOOKUP(A1176,'Hospitalisation Details'!$A$1:$R$2344,15,0) -> tier - 3 | P1176: =VLOOKUP(A1176,'Hospitalisation Details'!$A$1:$R$2344,16,0) -> R1016 | Q1176: =VLOOKUP(A1176,'Hospitalisation Details'!$A$1:$R$2344,18,0) -> 50.444901
A1177: Id1176 | B1177: =VLOOKUP(A1177,'Customer Name'!A1176:E3511,4,0) -> Andrew W | C1177: =VLOOKUP(A1177,Table7[#All],2,0) -> 23.01 | D1177: =VLOOKUP(A1177,Table7[#All],3,0) -> 6.04 | E1177: =VLOOKUP(A1177,Table7[#All],4,0) -> yes | F1177: =VLOOKUP(A1177,Table7[#All],5,0) -> No | G1177: =VLOOKUP(A1177,Table7[#All],6,0) -> No | H1177: =VLOOKUP(A1177,'Medical Examination'!A1176:M3511,11,0) -> 1 | I1177: =VLOOKUP(A1177,'Medical Examination'!A1176:M3511,10,0) -> No | J1177: =VLOOKUP(A1177,'Medical Examination'!A1176:M3511,12,0) -> Normal Weight | K1177: =VLOOKUP(A1177,'Medical Examination'!A1176:M3511,13,0) -> Prediabetes | L1177: =VLOOKUP(A1177,'Hospitalisation Details'!A6:R2349,17,0) -> 15-Dec-1964 | M1177: =VLOOKUP(A1177,'Hospitalisation Details'!$A$1:$R$2344,6,0) -> 9597.63 | N1177: =VLOOKUP(A1177,'Hospitalisation Details'!$A$1:$R$2344,14,0) -> tier - 3 | O1177: =VLOOKUP(A1177,'Hospitalisation Details'!$A$1:$R$2344,15,0) -> tier - 3 | P1177: =VLOOKUP(A1177,'Hospitalisation Details'!$A$1:$R$2344,16,0) -> R1013 | Q1177: =VLOOKUP(A1177,'Hospitalisation Details'!$A$1:$R$2344,18,0) -> 58.477755
A1178: Id1177 | B1178: =VLOOKUP(A1178,'Customer Name'!A1177:E3512,4,0) -> Mark G | C1178: =VLOOKUP(A1178,Table7[#All],2,0) -> 31.39 | D1178: =VLOOKUP(A1178,Table7[#All],3,0) -> 8.85 | E1178: =VLOOKUP(A1178,Table7[#All],4,0) -> yes | F1178: =VLOOKUP(A1178,Table7[#All],5,0) -> No | G1178: =VLOOKUP(A1178,Table7[#All],6,0) -> No | H1178: =VLOOKUP(A1178,'Medical Examination'!A1177:M3512,11,0) -> 0 | I1178: =VLOOKUP(A1178,'Medical Examination'!A1177:M3512,10,0) -> No | J1178: =VLOOKUP(A1178,'Medical Examination'!A1177:M3512,12,0) -> Obesity | K1178: =VLOOKUP(A1178,'Medical Examination'!A1177:M3512,13,0) -> Diabetes | L1178: =VLOOKUP(A1178,'Hospitalisation Details'!A7:R2350,17,0) -> 18-Oct-1981 | M1178: =VLOOKUP(A1178,'Hospitalisation Details'!$A$1:$R$2344,6,0) -> 9584.04 | N1178: =VLOOKUP(A1178,'Hospitalisation Details'!$A$1:$R$2344,14,0) -> tier - 2 | O1178: =VLOOKUP(A1178,'Hospitalisation Details'!$A$1:$R$2344,15,0) -> tier - 1 | P1178: =VLOOKUP(A1178,'Hospitalisation Details'!$A$1:$R$2344,16,0) -> R1021 | Q1178: =VLOOKUP(A1178,'Hospitalisation Details'!$A$1:$R$2344,18,0) -> 41.639223
A1179: Id1178 | B1179: =VLOOKUP(A1179,'Customer Name'!A1178:E3513,4,0) -> Kasey E. | C1179: =VLOOKUP(A1179,Table7[#All],2,0) -> 34.77 | D1179: =VLOOKUP(A1179,Table7[#All],3,0) -> 10.54 | E1179: =VLOOKUP(A1179,Table7[#All],4,0) -> No | F1179: =VLOOKUP(A1179,Table7[#All],5,0) -> No | G1179: =VLOOKUP(A1179,Table7[#All],6,0) -> No | H1179: =VLOOKUP(A1179,'Medical Examination'!A1178:M3513,11,0) -> 2 | I1179: =VLOOKUP(A1179,'Medical Examination'!A1178:M3513,10,0) -> No | J1179: =VLOOKUP(A1179,'Medical Examination'!A1178:M3513,12,0) -> Obesity | K1179: =VLOOKUP(A1179,'Medical Examination'!A1178:M3513,13,0) -> Diabetes | L1179: =VLOOKUP(A1179,'Hospitalisation Details'!A8:R2351,17,0) -> 28-Nov-1973 | M1179: =VLOOKUP(A1179,'Hospitalisation Details'!$A$1:$R$2344,6,0) -> 9583.89 | N1179: =VLOOKUP(A1179,'Hospitalisation Details'!$A$1:$R$2344,14,0) -> tier - 2 | O1179: =VLOOKUP(A1179,'Hospitalisation Details'!$A$1:$R$2344,15,0) -> tier - 3 | P1179: =VLOOKUP(A1179,'Hospitalisation Details'!$A$1:$R$2344,16,0) -> R1012 | Q1179: =VLOOKUP(A1179,'Hospitalisation Details'!$A$1:$R$2344,18,0) -> 49.526977
A1180: Id1179 | B1180: =VLOOKUP(A1180,'Customer Name'!A1179:E3514,4,0) -> Jeff | C1180: =VLOOKUP(A1180,Table7[#All],2,0) -> 24.48 | D1180: =VLOOKUP(A1180,Table7[#All],3,0) -> 4.37 | E1180: =VLOOKUP(A1180,Table7[#All],4,0) -> yes | F1180: =VLOOKUP(A1180,Table7[#All],5,0) -> No | G1180: =VLOOKUP(A1180,Table7[#All],6,0) -> No | H1180: =VLOOKUP(A1180,'Medical Examination'!A1179:M3514,11,0) -> 2 | I1180: =VLOOKUP(A1180,'Medical Examination'!A1179:M3514,10,0) -> No | J1180: =VLOOKUP(A1180,'Medical Examination'!A1179:M3514,12,0) -> Normal Weight | K1180: =VLOOKUP(A1180,'Medical Examination'!A1179:M3514,13,0) -> Normal | L1180: =VLOOKUP(A1180,'Hospitalisation Details'!A9:R2352,17,0) -> 4-Dec-1966 | M1180: =VLOOKUP(A1180,'Hospitalisation Details'!$A$1:$R$2344,6,0) -> 9582.54 | N1180: =VLOOKUP(A1180,'Hospitalisation Details'!$A$1:$R$2344,14,0) -> tier - 3 | O1180: =VLOOKUP(A1180,'Hospitalisation Details'!$A$1:$R$2344,15,0) -> tier - 2 | P1180: =VLOOKUP(A1180,'Hospitalisation Details'!$A$1:$R$2344,16,0) -> R1013 | Q1180: =VLOOKUP(A1180,'Hospitalisation Details'!$A$1:$R$2344,18,0) -> 56.510574
A1181: Id1180 | B1181: =VLOOKUP(A1181,'Customer Name'!A1180:E3515,4,0) -> Amy | C1181: =VLOOKUP(A1181,Table7[#All],2,0) -> 22.61 | D1181: =VLOOKUP(A1181,Table7[#All],3,0) -> 9.63 | E1181: =VLOOKUP(A1181,Table7[#All],4,0) -> No | F1181: =VLOOKUP(A1181,Table7[#All],5,0) -> No | G1181: =VLOOKUP(A1181,Table7[#All],6,0) -> No | H1181: =VLOOKUP(A1181,'Medical Examination'!A1180:M3515,11,0) -> 2 | I1181: =VLOOKUP(A1181,'Medical Examination'!A1180:M3515,10,0) -> No | J1181: =VLOOKUP(A1181,'Medical Examination'!A1180:M3515,12,0) -> Normal Weight | K1181: =VLOOKUP(A1181,'Medical Examination'!A1180:M3515,13,0) -> Diabetes | L1181: =VLOOKUP(A1181,'Hospitalisation Details'!A10:R2353,17,0) -> 1-Dec-1973 | M1181: =VLOOKUP(A1181,'Hospitalisation Details'!$A$1:$R$2344,6,0) -> 9566.99 | N1181: =VLOOKUP(A1181,'Hospitalisation Details'!$A$1:$R$2344,14,0) -> tier - 2 | O1181: =VLOOKUP(A1181,'Hospitalisation Details'!$A$1:$R$2344,15,0) -> tier - 1 | P1181: =VLOOKUP(A1181,'Hospitalisation Details'!$A$1:$R$2344,16,0) -> R1012 | Q1181: =VLOOKUP(A1181,'Hospitalisation Details'!$A$1:$R$2344,18,0) -> 49.518763
A1182: Id1181 | B1182: =VLOOKUP(A1182,'Customer Name'!A1181:E3516,4,0) -> Adam | C1182: =VLOOKUP(A1182,Table7[#All],2,0) -> 34.3 | D1182: =VLOOKUP(A1182,Table7[#All],3,0) -> 10.37 | E1182: =VLOOKUP(A1182,Table7[#All],4,0) -> No | F1182: =VLOOKUP(A1182,Table7[#All],5,0) -> No | G1182: =VLOOKUP(A1182,Table7[#All],6,0) -> No | H1182: =VLOOKUP(A1182,'Medical Examination'!A1181:M3516,11,0) -> 0 | I1182: =VLOOKUP(A1182,'Medical Examination'!A1181:M3516,10,0) -> No | J1182: =VLOOKUP(A1182,'Medical Examination'!A1181:M3516,12,0) -> Obesity | K1182: =VLOOKUP(A1182,'Medical Examination'!A1181:M3516,13,0) -> Diabetes | L1182: =VLOOKUP(A1182,'Hospitalisation Details'!A11:R2354,17,0) -> 14-Aug-1974 | M1182: =VLOOKUP(A1182,'Hospitalisation Details'!$A$1:$R$2344,6,0) -> 9563.03 | N1182: =VLOOKUP(A1182,'Hospitalisation Details'!$A$1:$R$2344,14,0) -> tier - 3 | O1182: =VLOOKUP(A1182,'Hospitalisation Details'!$A$1:$R$2344,15,0) -> tier - 1 | P1182: =VLOOKUP(A1182,'Hospitalisation Details'!$A$1:$R$2344,16,0) -> R1011 | Q1182: =VLOOKUP(A1182,'Hospitalisation Details'!$A$1:$R$2344,18,0) -> 48.817216
A1183: Id1182 | B1183: =VLOOKUP(A1183,'Customer Name'!A1182:E3517,4,0) -> Kristin M | C1183: =VLOOKUP(A1183,Table7[#All],2,0) -> 46.09 | D1183: =VLOOKUP(A1183,Table7[#All],3,0) -> 5.44 | E1183: =VLOOKUP(A1183,Table7[#All],4,0) -> No | F1183: =VLOOKUP(A1183,Table7[#All],5,0) -> No | G1183: =VLOOKUP(A1183,Table7[#All],6,0) -> No | H1183: =VLOOKUP(A1183,'Medical Examination'!A1182:M3517,11,0) -> 2 | I1183: =VLOOKUP(A1183,'Medical Examination'!A1182:M3517,10,0) -> No | J1183: =VLOOKUP(A1183,'Medical Examination'!A1182:M3517,12,0) -> Obesity | K1183: =VLOOKUP(A1183,'Medical Examination'!A1182:M3517,13,0) -> Normal | L1183: =VLOOKUP(A1183,'Hospitalisation Details'!A12:R2355,17,0) -> 22-Sep-1972 | M1183: =VLOOKUP(A1183,'Hospitalisation Details'!$A$1:$R$2344,6,0) -> 9549.57 | N1183: =VLOOKUP(A1183,'Hospitalisation Details'!$A$1:$R$2344,14,0) -> tier - 2 | O1183: =VLOOKUP(A1183,'Hospitalisation Details'!$A$1:$R$2344,15,0) -> tier - 1 | P1183: =VLOOKUP(A1183,'Hospitalisation Details'!$A$1:$R$2344,16,0) -> R1013 | Q1183: =VLOOKUP(A1183,'Hospitalisation Details'!$A$1:$R$2344,18,0) -> 50.707734
... A1754: Id1753 | B1754: =VLOOKUP(A1754,'Customer Name'!A1753:E4088,4,0) -> Grant A | C1754: =VLOOKUP(A1754,Table7[#All],2,0) -> 15.47 | D1754: =VLOOKUP(A1754,Table7[#All],3,0) -> 8.43 | E1754: =VLOOKUP(A1754,Table7[#All],4,0) -> No | F1754: =VLOOKUP(A1754,Table7[#All],5,0) -> No | G1754: =VLOOKUP(A1754,Table7[#All],6,0) -> No | H1754: =VLOOKUP(A1754,'Medical Examination'!A1753:M4088,11,0) -> 0 | I1754: =VLOOKUP(A1754,'Medical Examination'!A1753:M4088,10,0) -> No | J1754: =VLOOKUP(A1754,'Medical Examination'!A1753:M4088,12,0) -> Underweight | K1754: =VLOOKUP(A1754,'Medical Examination'!A1753:M4088,13,0) -> Diabetes | L1754: =VLOOKUP(A1754,'Hospitalisation Details'!A583:R2926,17,0) -> 22-Nov-1978 | M1754: =VLOOKUP(A1754,'Hospitalisation Details'!$A$1:$R$2344,6,0) -> 5077.19 | N1754: =VLOOKUP(A1754,'Hospitalisation Details'!$A$1:$R$2344,14,0) -> tier - 2 | O1754: =VLOOKUP(A1754,'Hospitalisation Details'!$A$1:$R$2344,15,0) -> tier - 3 | P1754: =VLOOKUP(A1754,'Hospitalisation Details'!$A$1:$R$2344,16,0) -> R1012 | Q1754: =VLOOKUP(A1754,'Hospitalisation Details'!$A$1:$R$2344,18,0) -> 44.54342
